Workbook

Sheet ANÁLISIS DE RAZONES
A1: Análisis de Razones
D4: Razón de Solvencia | G4: =+Balance!F9/Balance!F23 -> 3.2258065 | H4: El promedio de la Industria es de 4.2
G5: =+Balance!G9/Balance!G23 -> 3.6818182 | H5: Año anterior
D8: Razón de Prueba Rápida o Ácida | G8: =+(Balance!F9-Balance!F7)/Balance!F23 -> 1.2419355 | H8: El promedio de la Industria es de 2.2
G9: =+(Balance!G9-Balance!G7)/Balance!G23 -> 1.7954545 | H9: Año anterior
D11: Razón de Rotación de Inventario | G11: =+'Estado de Resultados'!I4/Balance!F7 -> 4.8780488 | H11: El promedio de la Industria es de 10.9
G12: =+'Estado de Resultados'!J4/Balance!G7 -> 6.8674699 | H12: Año anterior
D15: Razón de Días pendientes de cobro | G15: =+Balance!F6/('Estado de Resultados'!I4/365) -> 45.625 | H15: El promedio de la Industria es de 36 días
G16: =+Balance!G6/('Estado de Resultados'!J4/365) -> 40.342105 | H16: Año anterior
D18: Razón de Rotación de Activo Fijo Neto | G18: =+'Estado de Resultados'!I4/Balance!F14 -> 3 | H18: El promedio de la Industria es de 2.8
G19: =+'Estado de Resultados'!J4/Balance!G14 -> 3.2758621 | H19: Año anterior
D21: Razón de Rotación de Activo Contable | G21: =+'Estado de Resultados'!I4/Balance!F16 -> 1.5 | H21: El promedio de la Industria es de 1.8
G22: =+'Estado de Resultados'!J4/Balance!G16 -> 1.6964286 | H22: Año anterior
D24: Razón de Endeudamiento | G24: =+(Balance!F22+Balance!F26)/(Balance!F22+Balance!F26+Balance!F33) -> 0.47777778 | H24: El promedio de la Industria es de 36.4%
D25: (Capital Total = Deuda+Capital) | G25: =+(Balance!G22+Balance!G26)/(Balance!G22+Balance!G26+Balance!G33) -> 0.42105263 | H25: Año anterior
D27: Razón de Cobertura de Intereses | G27: =+'Estado de Resultados'!I8/'Estado de Resultados'!I9 -> 3.225 | H27: El promedio de la Industria es de 6.0
G28: =+'Estado de Resultados'!J8/'Estado de Resultados'!J9 -> 4.3833333 | H28: Año anterior
D30: Margen de Operación | G30: =+'Estado de Resultados'!I8/'Estado de Resultados'!I4 -> 0.0946 | H30: El promedio de la Industria es de 10%
G31: =+'Estado de Resultados'!J8/'Estado de Resultados'!J4 -> 0.092280702 | H31: Año anterior
D33: Margen de Utilidad Neto | G33: =+'Estado de Resultados'!I12/'Estado de Resultados'!I4 -> 0.03916 | H33: El promedio de la Industria es de 5%
G34: =+'Estado de Resultados'!J12/'Estado de Resultados'!J4 -> 0.042736842 | H34: Año anterior
D36: Rendimiento sobre Activo Contable - ROA | G36: =+'Estado de Resultados'!I12/Balance!F16 -> 0.05874 | H36: El promedio de la Industria es de 9%
G37: =+'Estado de Resultados'!J12/Balance!G16 -> 0.0725 | H37: Año anterior
D39: Rendimiento del Capital Común - ROE | G39: =+'Estado de Resultados'!I12/Balance!F33 -> 0.12497872 | H39: El promedio de la Industria es de 15%
G40: =+'Estado de Resultados'!J12/Balance!G33 -> 0.13840909 | H40: Año anterior
D42: Rendimiento del Capital Invertido - ROIC | G42: =+'Estado de Resultados'!I8*(1-0.4)/(Balance!F33+Balance!F26+Balance!F22) -> 0.0946 | H42: El promedio de la Industria es de 10.8%
G43: =+'Estado de Resultados'!J8*(1-0.4)/(Balance!G33+Balance!G26+Balance!G22) -> 0.10381579 | H43: Año anterior
D46: Ejercicio Rápido
D48: Ventas | G48: 20000
D49: Ingreso Neto | G49: 1000
D50: Activo Contable | G50: 10000 | H50: ES UNA SIMPLIFICACIÓN YA QUE NO HAY OTROS PASIVOS
D51: Capital Común | G51: 5000
D52: Deuda generadora de Intereses | G52: 5000
D53: Tasa de Interés sobre Deuda | G53: 0.05
D54: Tasa Impositiva | G54: 0.4
D56: Margen de Utilidad Neto | G56: =+G49/G48 -> 0.05
D57: ROA | G57: =+G49/G50 -> 0.1
D58: ROE | G58: =+G49/G51 -> 0.2
D59: ROIC | G59: =+((G49/(1-G54)+G53*G52)/G50)*(1-G54) -> 0.115
E61: EBIT*(1-TAX)/(CAPITAL+DEUDA) | G61: =+G62*(1-G54)/(G51+G52) -> 0.115
...

Sheet DuPont
C3: ROE | D3: INGRESO NETO | F3: =+'Estado de Resultados'!$I$12 -> 117.48 | G3: = | H3: =+'Estado de Resultados'!I12/Balance!F33 -> 0.12497872
D4: CAPITAL COMÚN | F4: =+Balance!$F$33 -> 940
D6: INGRESO NETO | E6: x | F6: ACTIVO CONTABLE
D7: ACTIVO CONTABLE | F7: CAPITAL COMÚN
D9: INGRESO NETO | E9: x | F9: VENTAS | G9: x | H9: ACTIVO CONTABLE
D10: VENTAS | F10: ACTIVO CONTABLE | H10: CAPITAL COMÚN
D12: MARGEN DE UTILIDAD | F12: ROTACIÓN DEL ACTIVO | H12: MULTIPL. DEL CAPITAL
D14: =+'Estado de Resultados'!I12/'Estado de Resultados'!I4 -> 0.03916 | E14: x | F14: =+'Estado de Resultados'!I4/Balance!F16 -> 1.5 | G14: x | H14: =+Balance!F16/Balance!F33 -> 2.1276596 | I14: = | J14: =+D14*F14*H14 -> 0.12497872

Sheet LEVERAGE
B1: Empresa NO Apalancada | K1: Empresa Apalancada
B3: Activo Circulante | D3: 50 | F3: Deuda | I3: 0 | K3: Activo Circulante | M3: 50 | O3: Deuda | R3: 50
B4: Activo Fijo | D4: 50 | F4: Capital Común | I4: 100 | K4: Activo Fijo | M4: 50 | O4: Capital Común | R4: 50
B5: Activo Contable | D5: 100 | F5: Pasivo Contable + Capital | I5: 100 | K5: Activo Contable | M5: 100 | O5: Pasivo Contable + Capital | R5: 100
G7: Mercado | P7: Mercado
G8: Bueno | H8: Esperado | I8: Malo | P8: Bueno | Q8: Esperado | R8: Malo
B9: Ventas | G9: 150 | H9: 100 | I9: 75 | K9: Ventas | P9: 150 | Q9: 100 | R9: 75
B10: Costos de Operación | K10: Costos de Operación
C11: Fijos | G11: 45 | H11: 45 | I11: 45 | L11: Fijos | P11: 45 | Q11: 45 | R11: 45
C12: Variables | G12: 60 | H12: 40 | I12: 30 | L12: Variables | P12: 60 | Q12: 40 | R12: 30
C13: Totales | G13: =SUM(G11:G12) -> 105 | H13: =SUM(H11:H12) -> 85 | I13: =SUM(I11:I12) -> 75 | L13: Totales | P13: =SUM(P11:P12) -> 105 | Q13: =SUM(Q11:Q12) -> 85 | R13: =SUM(R11:R12) -> 75
B14: Ingreso de Operaciones (EBIT) | G14: =+G9-G13 -> 45 | H14: =+H9-H13 -> 15 | I14: =+I9-I13 -> 0 | K14: Ingreso de Operaciones (EBIT) | P14: =+P9-P13 -> 45 | Q14: =+Q9-Q13 -> 15 | R14: =+R9-R13 -> 0
B15: Intereses (Tasa 10%) | G15: 0 | H15: 0 | I15: 0 | K15: Intereses (Tasa 10%) | P15: 5 | Q15: 5 | R15: 5
B16: Ganancias antes de Impuestos (EBT) | G16: =+G14-G15 -> 45 | H16: =+H14-H15 -> 15 | I16: =+I14-I15 -> 0 | K16: Ganancias antes de Impuestos (EBT) | P16: =+P14-P15 -> 40 | Q16: =+Q14-Q15 -> 10 | R16: =+R14-R15 -> -5
B17: Tax 40% | G17: =0.4*G16 -> 18 | H17: =0.4*H16 -> 6 | I17: =0.4*I16 -> 0 | K17: Tax 40% | P17: =0.4*P16 -> 16 | Q17: =0.4*Q16 -> 4 | R17: 0 | S17: Se asume que no hay recupero de impuestos
B18: Ingreso Neto (NI) | G18: =+G16-G17 -> 27 | H18: =+H16-H17 -> 9 | I18: =+I16-I17 -> 0 | K18: Ingreso Neto (NI) | P18: =+P16-P17 -> 24 | Q18: =+Q16-Q17 -> 6 | R18: =+R16-R17 -> -5
B19: ROE | G19: =+G18/$I$4 -> 0.27 | H19: =+H18/$I$4 -> 0.09 | I19: =+I18/$I$4 -> 0 | K19: ROE | P19: =+P18/$R$4 -> 0.48 | Q19: =+Q18/$R$4 -> 0.12 | R19: =+R18/$R$4 -> -0.1

Sheet Balance
F2: 2018 | G2: 2017 | I2: Composición Activo Circulante | L2: Sobre Activo Contable
B3: Activos | I3: 2018 | J3: 2017
C4: Activo Circulante
D5: Efectivo y Equivalentes | F5: 10 | G5: 80 | I5: =+F5/F$9 -> 0.01 | J5: =+G5/G$9 -> 0.098765432 | L5: =+F5/F$16 -> 0.005 | M5: =+G5/G$16 -> 0.047619048
D6: Cuentas por Cobrar | F6: 375 | G6: 315 | I6: =+F6/F$9 -> 0.375 | J6: =+G6/G$9 -> 0.38888889 | L6: =+F6/F$16 -> 0.1875 | M6: =+G6/G$16 -> 0.1875
D7: Inventarios | F7: 615 | G7: 415 | I7: =+F7/F$9 -> 0.615 | J7: =+G7/G$9 -> 0.51234568 | L7: =+F7/F$16 -> 0.3075 | M7: =+G7/G$16 -> 0.24702381
D8: Efectivo Excedente | F8: 0 | G8: 0 | L8: =SUM(L5:L7) -> 0.5 | M8: =SUM(M5:M7) -> 0.48214286
D9: Activo Circulante Total | F9: =SUM(F5:F8) -> 1000 | G9: =SUM(G5:G8) -> 810 | I9: =+F9/F16 -> 0.5 | J9: =+G9/G16 -> 0.48214286
C11: Activo Fijo Neto
D12: Planta y Equipo Netos de depreciación | F12: 1000 | G12: 870
D13: Otros Activos LP | F13: 0 | G13: 0
D14: Activo Fijo Total | F14: =SUM(F12:F13) -> 1000 | G14: =SUM(G12:G13) -> 870
C16: Activo Contable | F16: =+F14+F9 -> 2000 | G16: =+G14+G9 -> 1680
B18: Pasivos y Capital
C19: Pasivo Circulante
D20: Cuentas por Pagar | F20: 60 | G20: 30 | I20: Capital de Trabajo Neto
D21: Acumulaciones | F21: 140 | G21: 130 | I21: Activo Circulante - Pasivo Circulante
D22: Obligaciones por Pagar | F22: 110 | G22: 60 | I22: =+F9-F23 -> 690 | J22: =+G9-G23 -> 590 | K22: Aumenta | L22: =+I22-J22 -> 100
D23: Pasivo Circulante Total | F23: =SUM(F20:F22) -> 310 | G23: =SUM(G20:G22) -> 220
I24: Capital Operativo Neto
C25: Deuda a Largo Plazo | I25: Activo Circ. Oper - Pasivo Circ. Oper.
D26: Bonos a LP | F26: 750 | G26: 580 | I26: =+F9-F8-(F23-F22) -> 800 | J26: =+G9-G8-(G23-G22) -> 650 | K26: Aumenta | L26: =+I26-J26 -> 150
C28: Pasivo Contable | F28: =+F23+F26 -> 1060 | G28: =+G23+G26 -> 800 | I28: Pasivo Remunerado
I29: Activo Circ. Oper - Pasivo Circ. Oper.
C30: Capital Contable | E30: Cantidad | I30: =+F22+F26 -> 860 | J30: =+G22+G26 -> 640 | K30: Aumenta pero …
D31: Acciones Comunes | E31: 50 | F31: 130 | G31: 130 | I31: =+I30/F28 -> 0.81132075 | J31: =+J30/G28 -> 0.8
D32: Ganancias Retenidas | F32: 810 | G32: 750
D33: Capital Contable Total | F33: =SUM(F31:F32) -> 940 | G33: =SUM(G31:G32) -> 880 | I33: Valor Contable por Acción
I34: =+F33/$E$31 -> 18.8 | J34: =+G33/$E$31 -> 17.6
C35: Pasivos y Capital Totales | F35: =+F33+F28 -> 2000 | G35: =+G33+G28 -> 1680

Sheet Estado de Resultados
I2: 2018 | J2: 2017
C4: Ventas Netas | I4: 3000 | J4: 2850
D5: Costos de operación (excl. Depreciación y Amortiz.) | I5: 2616.2 | J5: 2497
D6: Depreciación y Amortización | I6: 100 | J6: 90
C7: Costos de Operación totales | I7: =+I6+I5 -> 2716.2 | J7: =+J6+J5 -> 2587
C8: Ingreso de operaciones, Ganancias antes de int. e Imp. (EBIT) | I8: =+I4-I7 -> 283.8 | J8: =+J4-J7 -> 263 | L8: EBIT aumenta
D9: Menos intereses | I9: 88 | J9: 60
C10: Ganancias antes de Impuestos (EBT) | I10: =+I8-I9 -> 195.8 | J10: =+J8-J9 -> 203 | L10: EBT disminuye
D11: Impuestos (40%) | I11: =+I10*0.4 -> 78.32 | J11: =+J10*0.4 -> 81.2
C12: Ingreso neto | I12: =+I10-I11 -> 117.48 | J12: =+J10-J11 -> 121.8
C14: EBITDA | I14: =+I8+I6 -> 383.8 | J14: =+J8+J6 -> 353 | L14: EBITDA aumenta
C16: Dividendos totales | I16: 57.5 | J16: 53
C17: Adición a las Ganancias Retenidas = Ingreso Neto - Dividendos Totales | I17: =+I12-I16 -> 59.98 | J17: =+J12-J16 -> 68.8
C19: Datos por Acción (50.000.000) | F19: 50
C20: Precio de las Acciones Comunes - MERCADO | I20: 23.06 | J20: 26
C21: Ganancias por Acción (EPS) | I21: 2.35 | J21: 2.44
C22: Dividendos por Acción (DPS) | I22: 1.15 | J22: 1.06
C23: Valor Contable por Acción (BVPS) | I23: 18.8 | J23: 17.6
G25: 2018
C26: Ganancias por Acción (EPS) | G26: =+I12 -> 117.48 | H26: / | I26: =+F19 -> 50 | J26: =+G26/I26 -> 2.3496
C27: Dividendos por Acción (DPS) | G27: =+I16 -> 57.5 | H27: / | I27: =+F19 -> 50 | J27: =+G27/I27 -> 1.15
C28: Valor Contable por Acción (BVPS) | G28: =+Balance!F33 -> 940 | H28: / | I28: =+F19 -> 50 | J28: =+G28/I28 -> 18.8
G31: 2017
C32: Ganancias por Acción (EPS) | G32: =+J12 -> 121.8 | H32: / | I32: =+F19 -> 50 | J32: =+G32/I32 -> 2.436
C33: Dividendos por Acción (DPS) | G33: =+J16 -> 53 | H33: / | I33: =+I32 -> 50 | J33: =+G33/I33 -> 1.06
C34: Valor Contable por Acción (BVPS) | G34: =+Balance!G33 -> 880 | H34: / | I34: =+I33 -> 50 | J34: =+G34/I34 -> 17.6
