Workbook

Sheet DATOS PROY EXPANSION
B3: CASO "S" DE ALLIED
B5: INVERSION INICIAL EN EQUIPO EN 2019 | G5: 900000
B6: INVENTARIO AUMENTA EN 2019 | G6: 175000
B7: CUENTAS POR PAGAR AUMENTAN EN 2019 | G7: 75000
B8: CAMBIO EN EL NOWC EN 2019 | G8: =+G6-G7 -> 100000
B10: N= | C10: 4 | D10: AÑOS
B11: VENTAS | G11: UNIDADES
F12: 2020 | G12: 2685000
F13: 2021 | G13: 2600000
F14: 2022 | G14: 2525000
F15: 2023 | G15: 2450000
B17: PRECIO DE VENTA DE CADA UNIDAD | G17: 2
B19: COSTOS FIJOS DE ELABORACION | G19: 2000000 | H19: POR AÑO
B20: COSTOS VARIABLES POR UNIDAD
F21: 2020 | G21: 1.018
F22: 2021 | G22: 1.078
F23: 2022 | G23: 1.046
F24: 2023 | G24: 1.221
B26: DEPRECIACIÓN ACELERADA Y LINEAL PARA VER SU IMPACTO
B28: AL FINAL DEL PROYECTO EN 2023 ESPERA
C29: VALOR DE RECUPERACIÓN DEL EQUIPO | G29: 50000
C30: RECUPERAR EL NOWC DE | G30: 100000
B32: LA TASA IMPOSITIVA ES DEL | H32: 0.4
B34: EL WACC CON BASE EN EL RIESGO PERCIBIDO SE CALCULA EN EL | H34: 0.1

Sheet PROYECTO DE EXPANSION - CALCULO
F3: 0 | G3: 1 | H3: 2 | I3: 3 | J3: 4
B4: DESEMBOLSO INICIAL
D5: ACTIVOS FIJOS | F5: =-900000 -> -900000
D6: NOWC | F6: -100000
B8: FLUJOS DE EFECTIVO DE OPERACIONES
D9: VENTAS EN UNIDADES | G9: =+'DATOS PROY EXPANSION'!G12 -> 2685000 | H9: =+'DATOS PROY EXPANSION'!G13 -> 2600000 | I9: =+'DATOS PROY EXPANSION'!G14 -> 2525000 | J9: =+'DATOS PROY EXPANSION'!G15 -> 2450000
D10: PRECIO DE VENTA | G10: 2 | H10: 2 | I10: 2 | J10: 2
D11: COSTO VARIABLE | G11: =+'DATOS PROY EXPANSION'!G21 -> 1.018 | H11: =+'DATOS PROY EXPANSION'!G22 -> 1.078 | I11: =+'DATOS PROY EXPANSION'!G23 -> 1.046 | J11: =+'DATOS PROY EXPANSION'!G24 -> 1.221
D12: INGRESOS DE VENTAS | G12: =+G10*G9 -> 5370000 | H12: =+H10*H9 -> 5200000 | I12: =+I10*I9 -> 5050000 | J12: =+J10*J9 -> 4900000
D13: COSTOS VARIABLES | G13: =+G11*G9 -> 2733330 | H13: =+H11*H9 -> 2802800 | I13: =+I11*I9 -> 2641150 | J13: =+J11*J9 -> 2991450
D14: COSTOS FIJOS DE OPERACIÓN SIN D&A | G14: =+'DATOS PROY EXPANSION'!$G$19 -> 2000000 | H14: =+'DATOS PROY EXPANSION'!$G$19 -> 2000000 | I14: =+'DATOS PROY EXPANSION'!$G$19 -> 2000000 | J14: =+'DATOS PROY EXPANSION'!$G$19 -> 2000000
D15: DEPRECIACIÓN ACELERADA | G15: =-$F$5*0.33 -> 297000 | H15: =-$F$5*0.45 -> 405000 | I15: =-$F$5*0.15 -> 135000 | J15: =-$F$5*0.07 -> 63000
D16: COSTOS TOTALES DE OPERACIÓN | G16: =+SUM(G13:G15) -> 5030330 | H16: =+SUM(H13:H15) -> 5207800 | I16: =+SUM(I13:I15) -> 4776150 | J16: =+SUM(J13:J15) -> 5054450
D17: EBIT | G17: =+G12-G16 -> 339670 | H17: =+H12-H16 -> -7800 | I17: =+I12-I16 -> 273850 | J17: =+J12-J16 -> -154450
D18: IMPUESTOS SOBRE INGRESOS DE OPERACIÓN | E18: 0.4 | G18: =+$E$18*G17 -> 135868 | H18: =+$E$18*H17 -> -3120 | I18: =+$E$18*I17 -> 109540 | J18: =+$E$18*J17 -> -61780
D19: EBIT * (1-T) | G19: =+G17-G18 -> 203802 | H19: =+H17-H18 -> -4680 | I19: =+I17-I18 -> 164310 | J19: =+J17-J18 -> -92670
D21: EBIT * (1-T) + DEPRECIACIÓN ACELERADA | G21: =+G19+G15 -> 500802 | H21: =+H19+H15 -> 400320 | I21: =+I19+I15 -> 299310 | J21: =+J19+J15 -> -29670
B23: FLUJOS DE EFECTIVO TERMINALES
D24: VALOR DE RECUPERACIÓN GRAVADO COMO INGRESO ORDINARIO | J24: 50000
D25: IMPUESTOS SOBRE EL VALOR DE RECUPERACIÓN | J25: =+J24*E18 -> 20000
D26: VALOR DE RECUPERACIÓN DESPUÉS DE IMPUESTOS | J26: =+J24-J25 -> 30000
D27: NOWC | J27: 100000
J28: =+J27+J26 -> 130000
B30: FLUJOS DE EFECTIVOS DISPONIBLES DEL PROYECTO
B31: EBIT * (1-T) + D&A - GASTOS EN ACTIVOS FIJOS - INCREMENTO NOWC | F31: =+SUM(F5:F6) -> -1000000 | G31: =+G21 -> 500802 | H31: =+H21 -> 400320 | I31: =+I21 -> 299310 | J31: =+J21+J28 -> 100330
B32: o
B33: CON DEPRECIACIÓN LINEAL | F33: =+'AMORT LINEAL - EXPANSION'!F31 -> -1000000 | G33: =+'AMORT LINEAL - EXPANSION'!G31 -> 472002 | H33: =+'AMORT LINEAL - EXPANSION'!H31 -> 328320 | I33: =+'AMORT LINEAL - EXPANSION'!I31 -> 335310 | J33: =+'AMORT LINEAL - EXPANSION'!J31 -> 165130
B35: EVALUACIÓN DEL PROYECTO CON EL WACC DEL | E35: 0.1
E37: ACELERADA | F37: LINEAL
D38: NPV | E38: =+NPV(E35,G31:J31)+F31 -> 79520.294 | F38: =+'AMORT LINEAL - EXPANSION'!E38 -> 65140.948 | G38: OJO CON LA FÓRMULA DEL EXCEL
D39: IRR | E39: =+IRR(F31:J31,0.1) -> 0.14530088 | F39: =+IRR(F33:J33,0.1) -> 0.13474988
D40: MIRR | E40: =+MIRR(F31:J31,E35,E35) -> 0.12124466 | F40: =+MIRR(F33:J33,E35,E35) -> 0.11749208
D41: PERIODO DE RECUPERACIÓN | E41: =2+(-F31-G31-H31)/I31 -> 2.3303531 | F41: =2+(-F33-G33-H33)/I33 -> 2.5955027
B43: DÓNDE INCLUIRÍAMOS
D44: EFECTOS DE LA CANIBALIZACIÓN
D45: COSTOS DE OPORTUNIDAD DE ACTIVOS EXISTENTES
D46: COSTOS IRRECUPERABLES
D47: OTROS CAMBIOS
E48: VENTAS
E49: PRECIO DE VENTA
...

Sheet AMORT LINEAL - EXPANSION
F3: 0 | G3: 1 | H3: 2 | I3: 3 | J3: 4
B4: DESEMBOLSO INICIAL
D5: ACTIVOS FIJOS | F5: -900000
D6: NOWC | F6: -100000
B8: FLUJOS DE EFECTIVO DE OPERACIONES
D9: VENTAS EN UNIDADES | G9: =+'DATOS PROY EXPANSION'!G12 -> 2685000 | H9: =+'DATOS PROY EXPANSION'!G13 -> 2600000 | I9: =+'DATOS PROY EXPANSION'!G14 -> 2525000 | J9: =+'DATOS PROY EXPANSION'!G15 -> 2450000
D10: PRECIO DE VENTA | G10: 2 | H10: 2 | I10: 2 | J10: 2
D11: COSTO VARIABLE | G11: =+'DATOS PROY EXPANSION'!G21 -> 1.018 | H11: =+'DATOS PROY EXPANSION'!G22 -> 1.078 | I11: =+'DATOS PROY EXPANSION'!G23 -> 1.046 | J11: =+'DATOS PROY EXPANSION'!G24 -> 1.221
D12: INGRESOS DE VENTAS | G12: =+G10*G9 -> 5370000 | H12: =+H10*H9 -> 5200000 | I12: =+I10*I9 -> 5050000 | J12: =+J10*J9 -> 4900000
D13: COSTOS VARIABLES | G13: =+G11*G9 -> 2733330 | H13: =+H11*H9 -> 2802800 | I13: =+I11*I9 -> 2641150 | J13: =+J11*J9 -> 2991450
D14: COSTOS FIJOS DE OPERACIÓN SIN D&A | G14: =+'DATOS PROY EXPANSION'!$G$19 -> 2000000 | H14: =+'DATOS PROY EXPANSION'!$G$19 -> 2000000 | I14: =+'DATOS PROY EXPANSION'!$G$19 -> 2000000 | J14: =+'DATOS PROY EXPANSION'!$G$19 -> 2000000
D15: DEPRECIACIÓN ACELERADA | G15: =-$F$5*0.25 -> 225000 | H15: =-$F$5*0.25 -> 225000 | I15: =-$F$5*0.25 -> 225000 | J15: =-$F$5*0.25 -> 225000
D16: COSTOS TOTALES DE OPERACIÓN | G16: =+SUM(G13:G15) -> 4958330 | H16: =+SUM(H13:H15) -> 5027800 | I16: =+SUM(I13:I15) -> 4866150 | J16: =+SUM(J13:J15) -> 5216450
D17: EBIT | G17: =+G12-G16 -> 411670 | H17: =+H12-H16 -> 172200 | I17: =+I12-I16 -> 183850 | J17: =+J12-J16 -> -316450
D18: IMPUESTOS SOBRE INGRESOS DE OPERACIÓN | E18: 0.4 | G18: =+$E$18*G17 -> 164668 | H18: =+$E$18*H17 -> 68880 | I18: =+$E$18*I17 -> 73540 | J18: =+$E$18*J17 -> -126580
D19: EBIT * (1-T) | G19: =+G17-G18 -> 247002 | H19: =+H17-H18 -> 103320 | I19: =+I17-I18 -> 110310 | J19: =+J17-J18 -> -189870
D21: EBIT * (1-T) + DEPRECIACIÓN ACELERADA | G21: =+G19+G15 -> 472002 | H21: =+H19+H15 -> 328320 | I21: =+I19+I15 -> 335310 | J21: =+J19+J15 -> 35130
B23: FLUJOS DE EFECTIVO TERMINALES
D24: VALOR DE RECUPERACIÓN GRAVADO COMO INGRESO ORDINARIO | J24: 50000
D25: IMPUESTOS SOBRE EL VALOR DE RECUPERACIÓN | J25: =+J24*E18 -> 20000
D26: VALOR DE RECUPERACIÓN DESPUÉS DE IMPUESTOS | J26: =+J24-J25 -> 30000
D27: NOWC | J27: 100000
J28: =+J27+J26 -> 130000
B30: FLUJOS DE EFECTIVOS DISPONIBLES DEL PROYECTO
B31: EBIT * (1-T) + D&A - GASTOS EN ACTIVOS FIJOS - INCREMENTO NOWC | F31: =+SUM(F5:F6) -> -1000000 | G31: =+G21 -> 472002 | H31: =+H21 -> 328320 | I31: =+I21 -> 335310 | J31: =+J21+J28 -> 165130
B33: CON DEPRECIACIÓN LINEAL
B35: EVALUACIÓN DEL PROYECTO CON EL WACC DEL | E35: 0.1
E37: LINEAL
D38: NPV | E38: =+NPV(E35,G31:J31)+F31 -> 65140.948
D39: IRR
D40: MIRR
D41: PERIODO DE RECUPERACIÓN | E41: =2+(-F31-G31-H31)/I31 -> 2.5955027

Sheet DATOS - ANÁLISIS DE REEMPLAZO
B3: NO SE NECESITA NOWC ADICIONAL
B5: DATOS QUE APLICAN A AMBAS MÁQUINAS
B6: INGRESOS POR VENTAS, CONSTANTES LOS 4 AÑOS | G6: 2500000
B7: VIDA ESPERADA DE LAS DOS MÁQUINAS | G7: 4 | H7: AÑOS
B8: WACC PARA EL ANÁLISIS | G8: 0.1
B9: TASA IMPOSITIVA | G9: 0.4
B11: DATOS PARA LA MÁQUINA ANTIGUA
B12: VALOR DE MERCADO DE (RECUP = CONTABLE) DE LA MAQ A HOY | G12: 400000
B13: COSTOS LABORALES, DE MATERIALES Y OTROS POR AÑO | G13: 1000000
B14: DEPRECIACIÓN ANUAL DE LA MÁQUINA | G14: 100000
B16: DATOS PARA LA MÁQUINA NUEVA
B17: COSTO DE ADQUISICIÓN | G17: 2000000
B18: COSTOS LABORALES, DE MATERIALES Y OTROS POR AÑO | G18: 400000

Sheet PROY. DE REEMPLAZO - CALCULO
F3: 0 | G3: 1 | H3: 2 | I3: 3 | J3: 4
B4: DESEMBOLSO INICIAL MÁQUINA ANTIGUA
D5: ACTIVOS FIJOS | F5: 0
D6: NOWC | F6: 0
B8: FLUJOS DE EFECTIVO DE OPERACIONES
D9: INGRESOS DE VENTAS | G9: 2500000 | H9: 2500000 | I9: 2500000 | J9: 2500000
D10: COSTOS TOTALES DE OPERACIÓN SIN D&A | G10: 1000000 | H10: 1000000 | I10: 1000000 | J10: 1000000
D11: DEPRECIACIÓN LINEAL | G11: 100000 | H11: 100000 | I11: 100000 | J11: 100000
D12: COSTOS TOTALES DE OPERACIÓN | G12: =+SUM(G10:G11) -> 1100000 | H12: =+SUM(H10:H11) -> 1100000 | I12: =+SUM(I10:I11) -> 1100000 | J12: =+SUM(J10:J11) -> 1100000
D13: EBIT | G13: =+G9-G12 -> 1400000 | H13: =+H9-H12 -> 1400000 | I13: =+I9-I12 -> 1400000 | J13: =+J9-J12 -> 1400000
D14: IMPUESTOS SOBRE INGRESOS DE OPERACIÓN | E14: 0.4 | G14: =+$E$14*G13 -> 560000 | H14: =+$E$14*H13 -> 560000 | I14: =+$E$14*I13 -> 560000 | J14: =+$E$14*J13 -> 560000
D15: EBIT * (1-T) | G15: =+G13-G14 -> 840000 | H15: =+H13-H14 -> 840000 | I15: =+I13-I14 -> 840000 | J15: =+J13-J14 -> 840000
D17: FCF = EBIT * (1-T) + DEPRECIACIÓN - CAPEX - VAR. NOWC | G17: =+G15+G11 -> 940000 | H17: =+H15+H11 -> 940000 | I17: =+I15+I11 -> 940000 | J17: =+J15+J11 -> 940000
F19: 0 | G19: 1 | H19: 2 | I19: 3 | J19: 4
B20: DESEMBOLSO INICIAL MÁQUINA NUEVA
D21: ACTIVOS FIJOS | F21: -1600000 | G21: COSTO MENOS VENTA DE LA ANTIGUA
D22: NOWC | F22: 0
B24: FLUJOS DE EFECTIVO DE OPERACIONES
D25: INGRESOS DE VENTAS | G25: 2500000 | H25: 2500000 | I25: 2500000 | J25: 2500000
D26: COSTOS TOTALES DE OPERACIÓN SIN D&A | G26: 400000 | H26: 400000 | I26: 400000 | J26: 400000
D27: DEPRECIACIÓN LINEAL | G27: 660000 | H27: 900000 | I27: 300000 | J27: 140000
D28: COSTOS TOTALES DE OPERACIÓN | G28: =+SUM(G26:G27) -> 1060000 | H28: =+SUM(H26:H27) -> 1300000 | I28: =+SUM(I26:I27) -> 700000 | J28: =+SUM(J26:J27) -> 540000
D29: EBIT | G29: =+G25-G28 -> 1440000 | H29: =+H25-H28 -> 1200000 | I29: =+I25-I28 -> 1800000 | J29: =+J25-J28 -> 1960000
D30: IMPUESTOS SOBRE INGRESOS DE OPERACIÓN | E30: 0.4 | G30: =+$E$14*G29 -> 576000 | H30: =+$E$14*H29 -> 480000 | I30: =+$E$14*I29 -> 720000 | J30: =+$E$14*J29 -> 784000
D31: EBIT * (1-T) | G31: =+G29-G30 -> 864000 | H31: =+H29-H30 -> 720000 | I31: =+I29-I30 -> 1080000 | J31: =+J29-J30 -> 1176000
D33: FCF = EBIT * (1-T) + DEPRECIACIÓN - CAPEX - VAR. NOWC | F33: -1600000 | G33: =+G31+G27 -> 1524000 | H33: =+H31+H27 -> 1620000 | I33: =+I31+I27 -> 1380000 | J33: =+J31+J27 -> 1316000
B35: FLUJOS DE EFECTIVO INCREMENTALES Y EVALUACIÓN
D37: FC INCREMENTALES = CF Después - CF Antes | F37: =+F33-F17 -> -1600000 | G37: =+G33-G17 -> 584000 | H37: =+H33-H17 -> 680000 | I37: =+I33-I17 -> 440000 | J37: =+J33-J17 -> 376000
B40: EVALUACIÓN DEL PROYECTO CON EL WACC DEL | E40: 0.1
D42: NPV | E42: =+NPV(E40,G37:J37)+F37 -> 80284.134 | F42: OJO CON LA FÓRMULA DEL EXCEL
D43: IRR | E43: =+IRR(F37:J37,0.1) -> 0.12505076
D44: MIRR | E44: =+MIRR(F37:J37,E40,E40) -> 0.11354654
D45: PERIODO DE RECUPERACIÓN | E45: =2+(-F37-G37-H37)/I37 -> 2.7636364
B47: TAMBIÉN SE PUEDE RESOLVER CON LOS CF INCREMENTALES
F48: 0 | G48: 1 | H48: 2 | I48: 3 | J48: 4
D49: COSTO DE REEMPLAZAR LA MÁQUINA | F49: -1600000
D50: AHORROS EN COSTOS | G50: =+G10-G26 -> 600000 | H50: =+H10-H26 -> 600000 | I50: =+I10-I26 -> 600000 | J50: =+J10-J26 -> 600000
D51: AHORROS EN COSTOS DESPUÉS DE IMPUESTOS | G51: =+G50*(1-$E$30) -> 360000 | H51: =+H50*(1-$E$30) -> 360000 | I51: =+I50*(1-$E$30) -> 360000 | J51: =+J50*(1-$E$30) -> 360000
D53: INCREMENTO EN LA DEPRECIACIÓN | E53: NO GENERA CF | G53: =+G27-G11 -> 560000 | H53: =+H27-H11 -> 800000 | I53: =+I27-I11 -> 200000 | J53: =+J27-J11 -> 40000
D54: AHORRO EN IMPUESTOS POR LA DEPRECIACIÓN | G54: =+$E$30*G53 -> 224000 | H54: =+$E$30*H53 -> 320000 | I54: =+$E$30*I53 -> 80000 | J54: =+$E$30*J53 -> 16000
...

Sheet SENSIBILIDAD RIESGO "S"
F3: 0 | G3: 1 | H3: 2 | I3: 3 | J3: 4 | L3: VARIAR A 1.25; 1.00 O 0.75
B4: DESEMBOLSO INICIAL
D5: ACTIVOS FIJOS | F5: =-900000*L5 -> -900000 | L5: 1
D6: NOWC | F6: -100000
B8: FLUJOS DE EFECTIVO DE OPERACIONES
D9: VENTAS EN UNIDADES | G9: =(+'DATOS PROY EXPANSION'!G12)*(+$L$9) -> 2685000 | H9: =(+'DATOS PROY EXPANSION'!G13)*(+$L$9) -> 2600000 | I9: =(+'DATOS PROY EXPANSION'!G14)*(+$L$9) -> 2525000 | J9: =(+'DATOS PROY EXPANSION'!G15)*(+$L$9) -> 2450000 | L9: 1
D10: PRECIO DE VENTA | G10: =2*$L10 -> 2 | H10: =2*$L10 -> 2 | I10: =2*$L10 -> 2 | J10: =2*$L10 -> 2 | L10: 1
D11: COSTO VARIABLE | G11: =(+'DATOS PROY EXPANSION'!G21)*(+$L$11) -> 1.018 | H11: =(+'DATOS PROY EXPANSION'!G22)*(+$L$11) -> 1.078 | I11: =(+'DATOS PROY EXPANSION'!G23)*(+$L$11) -> 1.046 | J11: =(+'DATOS PROY EXPANSION'!G24)*(+$L$11) -> 1.221 | L11: 1
D12: INGRESOS DE VENTAS | G12: =+G10*G9 -> 5370000 | H12: =+H10*H9 -> 5200000 | I12: =+I10*I9 -> 5050000 | J12: =+J10*J9 -> 4900000
D13: COSTOS VARIABLES | G13: =+G11*G9 -> 2733330 | H13: =+H11*H9 -> 2802800 | I13: =+I11*I9 -> 2641150 | J13: =+J11*J9 -> 2991450
D14: COSTOS FIJOS DE OPERACIÓN SIN D&A | G14: =(+'DATOS PROY EXPANSION'!$G$19)*(+$L$14) -> 2000000 | H14: =(+'DATOS PROY EXPANSION'!$G$19)*(+$L$14) -> 2000000 | I14: =(+'DATOS PROY EXPANSION'!$G$19)*(+$L$14) -> 2000000 | J14: =(+'DATOS PROY EXPANSION'!$G$19)*(+$L$14) -> 2000000 | L14: 1
D15: DEPRECIACIÓN ACELERADA | G15: =-$F$5*0.33 -> 297000 | H15: =-$F$5*0.45 -> 405000 | I15: =-$F$5*0.15 -> 135000 | J15: =-$F$5*0.07 -> 63000
D16: COSTOS TOTALES DE OPERACIÓN | G16: =+SUM(G13:G15) -> 5030330 | H16: =+SUM(H13:H15) -> 5207800 | I16: =+SUM(I13:I15) -> 4776150 | J16: =+SUM(J13:J15) -> 5054450
D17: EBIT | G17: =+G12-G16 -> 339670 | H17: =+H12-H16 -> -7800 | I17: =+I12-I16 -> 273850 | J17: =+J12-J16 -> -154450
D18: IMPUESTOS SOBRE INGRESOS DE OPERACIÓN | E18: 0.4 | G18: =+$E$18*G17 -> 135868 | H18: =+$E$18*H17 -> -3120 | I18: =+$E$18*I17 -> 109540 | J18: =+$E$18*J17 -> -61780
D19: EBIT * (1-T) | G19: =+G17-G18 -> 203802 | H19: =+H17-H18 -> -4680 | I19: =+I17-I18 -> 164310 | J19: =+J17-J18 -> -92670
D21: EBIT * (1-T) + DEPRECIACIÓN ACELERADA | G21: =+G19+G15 -> 500802 | H21: =+H19+H15 -> 400320 | I21: =+I19+I15 -> 299310 | J21: =+J19+J15 -> -29670
B23: FLUJOS DE EFECTIVO TERMINALES
D24: VALOR DE RECUPERACIÓN GRAVADO COMO INGRESO ORDINARIO | J24: 50000
D25: IMPUESTOS SOBRE EL VALOR DE RECUPERACIÓN | J25: =+J24*E18 -> 20000
D26: VALOR DE RECUPERACIÓN DESPUÉS DE IMPUESTOS | J26: =+J24-J25 -> 30000
D27: NOWC | J27: 100000
J28: =+J27+J26 -> 130000
B30: FLUJOS DE EFECTIVOS DISPONIBLES DEL PROYECTO
B31: EBIT * (1-T) + D&A - GASTOS EN ACTIVOS FIJOS - INCREMENTO NOWC | F31: =+SUM(F5:F6) -> -1000000 | G31: =+G21 -> 500802 | H31: =+H21 -> 400320 | I31: =+I21 -> 299310 | J31: =+J21+J28 -> 100330
B32: o
B33: CON DEPRECIACIÓN LINEAL | F33: =+'AMORT LINEAL - EXPANSION'!F31 -> -1000000 | G33: =+'AMORT LINEAL - EXPANSION'!G31 -> 472002 | H33: =+'AMORT LINEAL - EXPANSION'!H31 -> 328320 | I33: =+'AMORT LINEAL - EXPANSION'!I31 -> 335310 | J33: =+'AMORT LINEAL - EXPANSION'!J31 -> 165130
B35: EVALUACIÓN DEL PROYECTO CON EL WACC DEL | E35: 0.1
E37: ACELERADA
D38: NPV | E38: =+NPV(E35,G31:J31)+F31 -> 79520.294
B41: ANÁLISIS DE LOS DOS CASOS EXTREMOS, Y EL BASE, Y SU VARIABILIDAD CON RELACIÓN AL NPV
F42: PROB
B43: PEOR ESCENARIO | E43: -4974508.8 | F43: 0.25 | G43: =+F43*(E43-$E$47)^2 -> 7.8887227e+12
B44: CASO BASE | E44: 79520.294 | F44: 0.5 | G44: =+F44*(E44-$E$47)^2 -> 1.5867875e+11
B45: MEJOR ESCENARIO | E45: 7386929.1 | F45: 0.25 | G45: =+F45*(E45-$E$47)^2 -> 1.1370599e+13
B47: NPV PROMEDIO O ESPERADO | E47: =+SUMPRODUCT(E43:E45,F43:F45) -> 642865.22 | G47: =+SUM(G43:G45)^0.5 -> 4406586.1 | H47: DESVIO
G48: =+G47/E47 -> 6.8546033 | H48: CV
B50: SI EL CV DEL PROYECTO PROMEDIO DE ALLIED ES DE 2.00, ESTO IMPLICA QUE ESTE PROYECTO
B51: ES MUCHO MÁS RIESGOSO Y DEBERÍA INCREMENTARSE EL WACC PARA AJUSTARSE AL RIESGO
B53: QUÉ PASARÍA SI ELEVAMOS EL WACC?
...

Sheet CADENAS DE REEMPLAZO Y EAA
B2: WACC | C2: 0.12
D3: 0 | E3: 1 | F3: 2 | G3: 3 | H3: 4 | I3: 5 | J3: 6
B5: PROYECTO C | D5: -40000 | E5: 8000 | F5: 14000 | G5: 13000 | H5: 12000 | I5: 11000 | J5: 10000
B6: NPV | C6: =+D5+NPV(C2,E5:J5) -> 6490.9382
B7: TIR | C7: =+IRR(D5:J5,0.1) -> 0.17470812
B9: PROYECTO F | D9: -20000 | E9: 7000 | F9: 13000 | G9: 12000
B10: NPV | C10: =+D9+NPV(C2,E9:G9) -> 5154.8834
B11: TIR | C11: =+IRR(D9:J9,0.1) -> 0.2519721
B13: CON CADENA DE REEMPLAZO EN PROYECTO F
B15: PROYECTO F | D15: -20000 | E15: 7000 | F15: 13000 | G15: 12000
G16: -20000 | H16: 7000 | I16: 13000 | J16: 12000
D17: =+SUM(D15:D16) -> -20000 | E17: =+SUM(E15:E16) -> 7000 | F17: =+SUM(F15:F16) -> 13000 | G17: =+SUM(G15:G16) -> -8000 | H17: =+SUM(H15:H16) -> 7000 | I17: =+SUM(I15:I16) -> 13000 | J17: =+SUM(J15:J16) -> 12000
B18: NPV | C18: =+D17+NPV(C2,E17:J17) -> 8824.0276
B19: TIR | C19: =+IRR(D17:J17,0.1) -> 0.2519721 | D19: OBVIAMENTE COINCIDENTE CON LA ANTERIOR
B21: CON ANUALIDAD ANUAL EQUIVALENTE
D23: PROYECTO C | F23: PROYECTO F
C25: PV | D25: =-C6 -> -6490.9382 | F25: =-C10 -> -5154.8834
C26: N | D26: 6 | F26: 3
C27: WACC | D27: 0.12 | F27: =+D27 -> 0.12
C28: FV | D28: 0 | F28: 0
C29: PMT=EAA | D29: =+PMT(D27,D26,D25,D28,0) -> 1578.7631 | F29: =+PMT(F27,F26,F25,F28,0) -> 2146.2304
B33: WACC | C33: 0.1
D34: 0 | E34: 1 | F34: 2 | G34: 3 | H34: 4
B36: PROYECTO A | D36: -2000 | E36: 1500 | F36: 1500 | G36: 1500 | H36: 1500
B37: NPV | C37: =+D36+NPV(C33,E36:J36) -> 2754.7982
B38: TIR | C38: =+IRR(D36:J36,0.1) -> 0.64842573
B41: WACC | C41: 0.1
D42: 0 | E42: 1 | F42: 2
B44: PROYECTO B | D44: -1500 | E44: 1750 | F44: 1750
B45: NPV | C45: =+D44+NPV(C41,E44:J44) -> 1537.1901
B46: TIR | C46: =+IRR(D44:J44,0.1) -> 0.81090999
B49: WACC | C49: 0.1
D50: 0 | E50: 1 | F50: 2 | G50: 3 | H50: 4
B52: PROYECTO B' | D52: -1500 | E52: 1750 | F52: 250 | G52: 1750 | H52: 1750
B53: NPV | C53: =+D52+NPV(C49,E52:J52) -> 2807.5951
B54: TIR | C54: =+IRR(D52:J52,0.1) -> 0.81090999
B56: EAA
E57: PROYECTO A | G57: PROYECTO B
D59: PV | E59: =-C37 -> -2754.7982 | G59: =-C45 -> -1537.1901
D60: N | E60: 4 | G60: 2
...
